<?xml version="1.0"?>
<robot xmlns:xacro="http://ros.org/wiki/xacro" name="robot_core">

  <!-- Include inertial macros -->
  <xacro:include filename="$(find diner_waitress_robot)/description/inertial_macros.xacro" />

  <!-- Base Link -->
  <link name="base_link">
    <visual>
      <geometry>
        <box size="0.4 0.3 0.1"/>
      </geometry>
      <origin xyz="0 0 0.05"/>
      <material name="grey">
        <color rgba="0.5 0.5 0.5 1.0"/>
      </material>
    </visual>
    <xacro:inertial_box mass="3.0" size="0.4 0.3 0.1"/>
  </link>

  <!-- Right Wheel -->
  <link name="right_wheel">
    <visual>
      <geometry>
        <cylinder radius="0.05" length="0.03"/>
      </geometry>
      <origin xyz="0 -0.15 0.05" rpy="1.5708 0 0"/>
      <material name="black"/>
    </visual>
    <xacro:inertial_cylinder mass="0.3" radius="0.05" length="0.03"/>
  </link>

  <joint name="right_wheel_joint" type="continuous">
    <parent link="base_link"/>
    <child link="right_wheel"/>
    <origin xyz="0 -0.15 0.05" rpy="0 0 0"/>
    <axis xyz="0 1 0"/>
    <limit effort="10.0" velocity="10.0"/>
  </joint>

  <!-- Left Wheel -->
  <link name="left_wheel">
    <visual>
      <geometry>
        <cylinder radius="0.05" length="0.03"/>
      </geometry>
      <origin xyz="0 0.15 0.05" rpy="1.5708 0 0"/>
      <material name="black"/>
    </visual>
    <xacro:inertial_cylinder mass="0.3" radius="0.05" length="0.03"/>
  </link>

  <joint name="left_wheel_joint" type="continuous">
    <parent link="base_link"/>
    <child link="left_wheel"/>
    <origin xyz="0 0.15 0.05" rpy="0 0 0"/>
    <axis xyz="0 1 0"/>
    <limit effort="10.0" velocity="10.0"/>
  </joint>

  <!-- Caster Wheel (bebas bergerak) -->
  <link name="caster_wheel">
    <visual>
      <geometry>
        <sphere radius="0.03"/>
      </geometry>
      <origin xyz="-0.15 0 0.03"/>
      <material name="black"/>
    </visual>
    <xacro:inertial_sphere mass="0.1" radius="0.03"/>
  </link>

  <joint name="caster_wheel_joint" type="fixed">
    <parent link="base_link"/>
    <child link="caster_wheel"/>
    <origin xyz="-0.15 0 0.03"/>
  </joint>

</robot>
